<?xml version="1.0" ?>

<robot name="lynx_rover" xmlns:xacro="http://www.ros.org/wiki/xacro">
  
  <xacro:include filename="$(find lynxbot_description)/urdf/common_properties.urdf.xacro" />

  <xacro:macro name="wheel_link" params="prefix origin_xyz origin_rpy">

    <link name="${prefix}_wheel">
  
   <inertial>
     <origin xyz="0 0 0" rpy="0 0 0"/>
     <mass value="100"/>
     <inertia ixx="0.15"  ixy="0"  ixz="0" iyy="0.15" iyz="0" izz="0.15" />
   </inertial>
      <visual>
        <geometry>
          <cylinder length="0.065" radius="0.055"/>
        </geometry>
        <origin xyz="${origin_xyz}" rpy="${origin_rpy}"/>
        <material name="blue">
          <color rgba="0 0 1 1"/>
        </material>
      </visual>
      <collision>
        <geometry>
          <cylinder length="0.065" radius="0.055"/>
        </geometry>
        <origin xyz="${origin_xyz}" rpy="${origin_rpy}"/>
      </collision>
    </link>
  </xacro:macro>

  <xacro:macro name="wheel_joint" params="prefix origin_xyz origin_rpy">
    <joint type="continuous" name="${prefix}_wheel_joint">
    <origin xyz="${origin_xyz}" rpy="${origin_rpy}"/>
    <child link="${prefix}_wheel"/>
    <parent link="chassis"/>
    <axis xyz="0 1 0" rpy="0 0 0"/>
    <limit effort="10000" velocity="1000"/>
    <joint_properties damping="20.0" friction="10.0"/>
  </joint>
  </xacro:macro>

</robot>
